<?xml version="1.0" encoding="utf-8"?>

<robot xmlns:xacro="http://www.ros.org/wiki/xacro">
  <xacro:macro name="stoch3_description" params="fixed">

    <!-- For KDL -->
    <xacro:if value="${fixed}">
      <link name="world">
      </link>

      <joint name="fixed" type="fixed">
        <parent link="world"/>
        <child link="base_link"/>
      </joint>
    </xacro:if>
    <xacro:unless value="${fixed}">
      <link name="world">
      </link>

      <joint name="world_joint" type="floating">
        <parent link="world"/>
        <child link="base_link"/>
      </joint>
    </xacro:unless>


    <link
      name="base_link">
      <inertial>
        <origin
          xyz="-0.00066643 -4.8401E-05 0.068162"
          rpy="0 0 0" />
        <mass
          value="9.7565" />
        <inertia
          ixx="0.028321"
          ixy="7.0431E-06"
          ixz="1.0437E-05"
          iyy="0.033624"
          iyz="-2.4398E-08"
          izz="0.053863" />
      </inertial>
      <visual>
        <origin
          xyz="0 0 0"
          rpy="0 0 0" />
        <geometry>
          <mesh
            filename="package://stoch3_description/meshes/base_link.STL" />
        </geometry>
        <material
          name="">
          <color
            rgba="0.75294 0.75294 0.75294 1" />
        </material>
      </visual>
      <collision>
        <origin
          xyz="0 0 0"
          rpy="0 0 0" />
        <geometry>
          <mesh
            filename="package://stoch3_description/meshes/base_link.STL" />
        </geometry>
      </collision>
    </link>
    <link
      name="fl_abd_link">
      <inertial>
        <origin
          xyz="0.061349 -0.019504 -7.6667E-06"
          rpy="0 0 0" />
        <mass
          value="0.94517" />
        <inertia
          ixx="0.00061416"
          ixy="5.7906E-07"
          ixz="-3.8412E-06"
          iyy="0.0010243"
          iyz="-1.6902E-06"
          izz="0.00060713" />
      </inertial>
      <visual>
        <origin
          xyz="0 0 0"
          rpy="0 0 0" />
        <geometry>
          <mesh
            filename="package://stoch3_description/meshes/fl_abd_link.STL" />
        </geometry>
        <material
          name="">
          <color
            rgba="0.79216 0.81961 0.93333 1" />
        </material>
      </visual>
      <collision>
        <origin
          xyz="0 0 0"
          rpy="0 0 0" />
        <geometry>
          <mesh
            filename="package://stoch3_description/meshes/fl_abd_link.STL" />
        </geometry>
      </collision>
    </link>
    <joint
      name="fl_abd_joint"
      type="revolute">
      <origin
        xyz="0.206917503877324 0.101500000000002 0.0540300000000024"
        rpy="0 0 0" />
      <parent
        link="base_link" />
      <child
        link="fl_abd_link" />
      <axis
        xyz="1 0 0" />
      <limit
        lower="-1.5708"
        upper="1.5708"
        effort="100"
        velocity="100" />
    </joint>
    <link
      name="fl_thigh_link">
      <inertial>
        <origin
          xyz="0.0014376 0.077483 -0.055275"
          rpy="0 0 0" />
        <mass
          value="2.4957" />
        <inertia
          ixx="0.0049396"
          ixy="4.7834E-05"
          ixz="-3.2241E-06"
          iyy="0.0054131"
          iyz="-1.5857E-06"
          izz="0.0011512" />
      </inertial>
      <visual>
        <origin
          xyz="0 0 0"
          rpy="0 0 0" />
        <geometry>
          <mesh
            filename="package://stoch3_description/meshes/fl_thigh_link.STL" />
        </geometry>
        <material
          name="">
          <color
            rgba="0.75294 0.75294 0.75294 1" />
        </material>
      </visual>
      <collision>
        <origin
          xyz="0 0 0"
          rpy="0 0 0" />
        <geometry>
          <mesh
            filename="package://stoch3_description/meshes/fl_thigh_link.STL" />
        </geometry>
      </collision>
    </link>
    <joint
      name="fl_hip_joint"
      type="revolute">
      <origin
        xyz="0.06378709521538 0.0139999999999987 0"
        rpy="0 -3.14584042145611E-05 0" />
      <parent
        link="fl_abd_link" />
      <child
        link="fl_thigh_link" />
      <axis
        xyz="0 1 0" />
      <limit
        lower="-1.57078"
        upper="3.14159"
        effort="100"
        velocity="100" />
    </joint>
    <link
      name="fl_shank_link">
      <inertial>
        <origin
          xyz="-0.014616 -6.6962E-07 -0.11828"
          rpy="0 0 0" />
        <mass
          value="0.37918" />
        <inertia
          ixx="0.0021646"
          ixy="5.617E-09"
          ixz="-4.4468E-05"
          iyy="0.0022225"
          iyz="3.9894E-08"
          izz="6.6686E-05" />
      </inertial>
      <visual>
        <origin
          xyz="0 0 0"
          rpy="0 0 0" />
        <geometry>
          <mesh
            filename="package://stoch3_description/meshes/fl_shank_link.STL" />
        </geometry>
        <material
          name="">
          <color
            rgba="0.79216 0.81961 0.93333 1" />
        </material>
      </visual>
      <collision>
        <origin
          xyz="0 0 0"
          rpy="0 0 0" />
        <geometry>
          <mesh
            filename="package://stoch3_description/meshes/fl_shank_link.STL" />
        </geometry>
      </collision>
    </link>
    <joint
      name="fl_knee_joint"
      type="revolute">
      <origin
        xyz="0 0.111399999999998 -0.296999999853041"
        rpy="0 3.14584042149928E-05 0" />
      <parent
        link="fl_thigh_link" />
      <child
        link="fl_shank_link" />
      <axis
        xyz="0 1 0" />
      <limit
        lower="-3.14159"
        upper="0"
        effort="100"
        velocity="100" />
    </joint>
    <link
      name="fr_abd_link">
      <inertial>
        <origin
          xyz="0.06156 0.019504 -0.00021624"
          rpy="0 0 0" />
        <mass
          value="0.94517" />
        <inertia
          ixx="0.00061326"
          ixy="3.2241E-07"
          ixz="1.5152E-08"
          iyy="0.0010243"
          iyz="-3.8552E-06"
          izz="0.00060803" />
      </inertial>
      <visual>
        <origin
          xyz="0 0 0"
          rpy="0 0 0" />
        <geometry>
          <mesh
            filename="package://stoch3_description/meshes/fr_abd_link.STL" />
        </geometry>
        <material
          name="">
          <color
            rgba="0.79216 0.81961 0.93333 1" />
        </material>
      </visual>
      <collision>
        <origin
          xyz="0 0 0"
          rpy="0 0 0" />
        <geometry>
          <mesh
            filename="package://stoch3_description/meshes/fr_abd_link.STL" />
        </geometry>
      </collision>
    </link>
    <joint
      name="fr_abd_joint"
      type="revolute">
      <origin
        xyz="0.206925357517166 -0.101499999999999 0.0540300000000003"
        rpy="0 0 0" />
      <parent
        link="base_link" />
      <child
        link="fr_abd_link" />
      <axis
        xyz="1 0 0" />
      <limit
        lower="-1.5708"
        upper="1.5708"
        effort="100"
        velocity="100" />
    </joint>
    <link
      name="fr_thigh_link">
      <inertial>
        <origin
          xyz="0.00144107858196152 -0.07748346487516 -0.0551703662273829"
          rpy="0 0 0" />
        <mass
          value="2.49567510872212" />
        <inertia
          ixx="0.00493964200419569"
          ixy="-4.78342957937469E-05"
          ixz="3.2241369041665E-06"
          iyy="0.00541305231980369"
          iyz="-1.61934782864799E-06"
          izz="0.00115115548345638" />
      </inertial>
      <visual>
        <origin
          xyz="0 0 0"
          rpy="0 0 0" />
        <geometry>
          <mesh
            filename="package://stoch3_description/meshes/fr_thigh_link.STL" />
        </geometry>
        <material
          name="">
          <color
            rgba="0.752941176470588 0.752941176470588 0.752941176470588 1" />
        </material>
      </visual>
      <collision>
        <origin
          xyz="0 0 0"
          rpy="0 0 0" />
        <geometry>
          <mesh
            filename="package://stoch3_description/meshes/fr_thigh_link.STL" />
        </geometry>
      </collision>
    </link>
    <joint
      name="fr_hip_joint"
      type="revolute">
      <origin
        xyz="0.06377924157554 -0.0139999999999988 0"
        rpy="0 3.145840420901E-05 0" />
      <parent
        link="fr_abd_link" />
      <child
        link="fr_thigh_link" />
      <axis
        xyz="0 1 0" />
      <limit
        lower="-1.57078"
        upper="3.14159"
        effort="100"
        velocity="100" />
    </joint>
    <link
      name="fr_shank_link">
      <inertial>
        <origin
          xyz="-0.014616 -6.6962E-07 -0.11828"
          rpy="0 0 0" />
        <mass
          value="0.37918" />
        <inertia
          ixx="0.0021646"
          ixy="5.617E-09"
          ixz="-4.4468E-05"
          iyy="0.0022225"
          iyz="3.9894E-08"
          izz="6.6686E-05" />
      </inertial>
      <visual>
        <origin
          xyz="0 0 0"
          rpy="0 0 0" />
        <geometry>
          <mesh
            filename="package://stoch3_description/meshes/fr_shank_link.STL" />
        </geometry>
        <material
          name="">
          <color
            rgba="0.79216 0.81961 0.93333 1" />
        </material>
      </visual>
      <collision>
        <origin
          xyz="0 0 0"
          rpy="0 0 0" />
        <geometry>
          <mesh
            filename="package://stoch3_description/meshes/fr_shank_link.STL" />
        </geometry>
      </collision>
    </link>
    <joint
      name="fr_knee_joint"
      type="revolute">
      <origin
        xyz="0 -0.111599999999999 -0.29699999985303"
        rpy="0 -3.14584042085783E-05 0" />
      <parent
        link="fr_thigh_link" />
      <child
        link="fr_shank_link" />
      <axis
        xyz="0 1 0" />
      <limit
        lower="-3.14159"
        upper="0"
        effort="100"
        velocity="100" />
    </joint>
    <link
      name="bl_abd_link">
      <inertial>
        <origin
          xyz="0.030793 -0.019504 -0.00042262"
          rpy="0 0 0" />
        <mass
          value="0.94517" />
        <inertia
          ixx="0.00061091"
          ixy="-9.6216E-07"
          ixz="-1.2691E-06"
          iyy="0.0010243"
          iyz="1.7068E-06"
          izz="0.00061038" />
      </inertial>
      <visual>
        <origin
          xyz="0 0 0"
          rpy="0 0 0" />
        <geometry>
          <mesh
            filename="package://stoch3_description/meshes/bl_abd_link.STL" />
        </geometry>
        <material
          name="">
          <color
            rgba="0.79216 0.81961 0.93333 1" />
        </material>
      </visual>
      <collision>
        <origin
          xyz="0 0 0"
          rpy="0 0 0" />
        <geometry>
          <mesh
            filename="package://stoch3_description/meshes/bl_abd_link.STL" />
        </geometry>
      </collision>
    </link>
    <joint
      name="bl_abd_joint"
      type="revolute">
      <origin
        xyz="-0.299402452130055 0.101499999999997 0.0540300000000009"
        rpy="0 0 0" />
      <parent
        link="base_link" />
      <child
        link="bl_abd_link" />
      <axis
        xyz="1 0 0" />
      <limit
        lower="-1.5708"
        upper="1.5708"
        effort="100"
        velocity="100" />
    </joint>
    <link
      name="bl_thigh_link">
      <inertial>
        <origin
          xyz="-0.00144107858108192 0.0774834648849106 -0.0551703662338023"
          rpy="0 0 0" />
        <mass
          value="2.49567510818258" />
        <inertia
          ixx="0.00493964200383586"
          ixy="-4.78342957989956E-05"
          ixz="-3.22413680518202E-06"
          iyy="0.0054130523194199"
          iyz="1.61934780851157E-06"
          izz="0.00115115548343042" />
      </inertial>
      <visual>
        <origin
          xyz="0 0 0"
          rpy="0 0 0" />
        <geometry>
          <mesh
            filename="package://stoch3_description/meshes/bl_thigh_link.STL" />
        </geometry>
        <material
          name="">
          <color
            rgba="0.752941176470588 0.752941176470588 0.752941176470588 1" />
        </material>
      </visual>
      <collision>
        <origin
          xyz="0 0 0"
          rpy="0 0 0" />
        <geometry>
          <mesh
            filename="package://stoch3_description/meshes/bl_thigh_link.STL" />
        </geometry>
      </collision>
    </link>
    <joint
      name="bl_hip_joint"
      type="revolute">
      <origin
        xyz="0.0286978530373435 0.0139999999999997 0"
        rpy="0 -3.14584042145611E-05 0" />
      <parent
        link="bl_abd_link" />
      <child
        link="bl_thigh_link" />
      <axis
        xyz="0 1 0" />
      <limit
        lower="-1.57078"
        upper="3.14159"
        effort="100"
        velocity="100" />
    </joint>
    <link
      name="bl_shank_link">
      <inertial>
        <origin
          xyz="-0.014616 -6.6962E-07 -0.11828"
          rpy="0 0 0" />
        <mass
          value="0.37918" />
        <inertia
          ixx="0.0021646"
          ixy="5.617E-09"
          ixz="-4.4468E-05"
          iyy="0.0022225"
          iyz="3.9894E-08"
          izz="6.6686E-05" />
      </inertial>
      <visual>
        <origin
          xyz="0 0 0"
          rpy="0 0 0" />
        <geometry>
          <mesh
            filename="package://stoch3_description/meshes/bl_shank_link.STL" />
        </geometry>
        <material
          name="">
          <color
            rgba="0.79216 0.81961 0.93333 1" />
        </material>
      </visual>
      <collision>
        <origin
          xyz="0 0 0"
          rpy="0 0 0" />
        <geometry>
          <mesh
            filename="package://stoch3_description/meshes/bl_shank_link.STL" />
        </geometry>
      </collision>
    </link>
    <joint
      name="bl_knee_joint"
      type="revolute">
      <origin
        xyz="0 0.111599999999496 -0.29699999985304"
        rpy="0 3.14584042094417E-05 0" />
      <parent
        link="bl_thigh_link" />
      <child
        link="bl_shank_link" />
      <axis
        xyz="0 1 0" />
      <limit
        lower="-3.14159"
        upper="0"
        effort="100"
        velocity="100" />
    </joint>
    <link
      name="br_abd_link">
      <inertial>
        <origin
          xyz="0.031108 0.019504 -1.7708E-05"
          rpy="0 0 0" />
        <mass
          value="0.94517" />
        <inertia
          ixx="0.00061475"
          ixy="8.7419E-07"
          ixz="3.1106E-06"
          iyy="0.0010243"
          iyz="1.7938E-06"
          izz="0.00060654" />
      </inertial>
      <visual>
        <origin
          xyz="0 0 0"
          rpy="0 0 0" />
        <geometry>
          <mesh
            filename="package://stoch3_description/meshes/br_abd_link.STL" />
        </geometry>
        <material
          name="">
          <color
            rgba="0.79216 0.81961 0.93333 1" />
        </material>
      </visual>
      <collision>
        <origin
          xyz="0 0 0"
          rpy="0 0 0" />
        <geometry>
          <mesh
            filename="package://stoch3_description/meshes/br_abd_link.STL" />
        </geometry>
      </collision>
    </link>
    <joint
      name="br_abd_joint"
      type="revolute">
      <origin
        xyz="-0.299402452130055 -0.101500000000005 0.0540300000000005"
        rpy="0 0 0" />
      <parent
        link="base_link" />
      <child
        link="br_abd_link" />
      <axis
        xyz="1 0 0" />
      <limit
        lower="-1.5708"
        upper="1.5708"
        effort="100"
        velocity="100" />
    </joint>
    <link
      name="br_thigh_link">
      <inertial>
        <origin
          xyz="-0.00150303818321485 -0.0774834645949825 -0.0552213173300917"
          rpy="0 0 0" />
        <mass
          value="2.49567512655825" />
        <inertia
          ixx="0.0049362160738861"
          ixy="4.96261951245898E-05"
          ixz="2.5269174510805E-06"
          iyy="0.00541305233737715"
          iyz="1.18125628096648E-07"
          izz="0.00115458143484649" />
      </inertial>
      <visual>
        <origin
          xyz="0 0 0"
          rpy="0 0 0" />
        <geometry>
          <mesh
            filename="package://stoch3_description/meshes/br_thigh_link.STL" />
        </geometry>
        <material
          name="">
          <color
            rgba="0.752941176470588 0.752941176470588 0.752941176470588 1" />
        </material>
      </visual>
      <collision>
        <origin
          xyz="0 0 0"
          rpy="0 0 0" />
        <geometry>
          <mesh
            filename="package://stoch3_description/meshes/br_thigh_link.STL" />
        </geometry>
      </collision>
    </link>
    <joint
      name="br_hip_joint"
      type="revolute">
      <origin
        xyz="0.0286978530373517 -0.0139999999999956 0"
        rpy="0 3.14584042201122E-05 0" />
      <parent
        link="br_abd_link" />
      <child
        link="br_thigh_link" />
      <axis
        xyz="0 1 0" />
      <limit
        lower="-1.57078"
        upper="3.14159"
        effort="100"
        velocity="100" />
    </joint>
    <link
      name="br_shank_link">
      <inertial>
        <origin
          xyz="-0.014616 -6.6962E-07 -0.11828"
          rpy="0 0 0" />
        <mass
          value="0.37918" />
        <inertia
          ixx="0.0021646"
          ixy="5.617E-09"
          ixz="-4.4468E-05"
          iyy="0.0022225"
          iyz="3.9894E-08"
          izz="6.6686E-05" />
      </inertial>
      <visual>
        <origin
          xyz="0 0 0"
          rpy="0 0 0" />
        <geometry>
          <mesh
            filename="package://stoch3_description/meshes/br_shank_link.STL" />
        </geometry>
        <material
          name="">
          <color
            rgba="0.79216 0.81961 0.93333 1" />
        </material>
      </visual>
      <collision>
        <origin
          xyz="0 0 0"
          rpy="0 0 0" />
        <geometry>
          <mesh
            filename="package://stoch3_description/meshes/br_shank_link.STL" />
        </geometry>
      </collision>
    </link>
    <joint
      name="br_knee_joint"
      type="revolute">
      <origin
        xyz="0 -0.111600000000005 -0.296999999853014"
        rpy="0 -3.14584042141294E-05 0" />
      <parent
        link="br_thigh_link" />
      <child
        link="br_shank_link" />
      <axis
        xyz="0 1 0" />
      <limit
        lower="-3.14159"
        upper="0"
        effort="100"
        velocity="100" />
    </joint>
  </xacro:macro>
</robot>
