<?xml version="1.0" encoding="utf-8"?>
<!-- =================================================================================== -->
<!-- |    This document was autogenerated by xacro from stoch3.urdf.xacro              | -->
<!-- |    EDITING THIS FILE BY HAND IS NOT RECOMMENDED                                 | -->
<!-- =================================================================================== -->
<robot name="stoch3">
  <link name="world">
      </link>
  <joint name="fixed" type="fixed">
    <parent link="world"/>
    <child link="base_link"/>
  </joint>
  <link name="base_link">
    <inertial>
      <origin rpy="0 0 0" xyz="-0.00066643 -4.8401E-05 0.068162"/>
      <mass value="9.7565"/>
      <inertia ixx="0.028321" ixy="7.0431E-06" ixz="1.0437E-05" iyy="0.033624" iyz="-2.4398E-08" izz="0.053863"/>
    </inertial>
    <visual>
      <origin rpy="0 0 0" xyz="0 0 0"/>
      <geometry>
        <mesh filename="package://stoch3_description/meshes/base_link.STL"/>
      </geometry>
      <material name="">
        <color rgba="0.75294 0.75294 0.75294 1"/>
      </material>
    </visual>
    <collision>
      <origin rpy="0 0 0" xyz="0 0 0"/>
      <geometry>
        <mesh filename="package://stoch3_description/meshes/base_link.STL"/>
      </geometry>
    </collision>
  </link>
  <link name="fl_abd_link">
    <inertial>
      <origin rpy="0 0 0" xyz="0.061349 -0.019504 -7.6667E-06"/>
      <mass value="0.94517"/>
      <inertia ixx="0.00061416" ixy="5.7906E-07" ixz="-3.8412E-06" iyy="0.0010243" iyz="-1.6902E-06" izz="0.00060713"/>
    </inertial>
    <visual>
      <origin rpy="0 0 0" xyz="0 0 0"/>
      <geometry>
        <mesh filename="package://stoch3_description/meshes/fl_abd_link.STL"/>
      </geometry>
      <material name="">
        <color rgba="0.79216 0.81961 0.93333 1"/>
      </material>
    </visual>
    <collision>
      <origin rpy="0 0 0" xyz="0 0 0"/>
      <geometry>
        <mesh filename="package://stoch3_description/meshes/fl_abd_link.STL"/>
      </geometry>
    </collision>
  </link>
  <joint name="fl_abd_joint" type="revolute">
    <origin rpy="0 0 0" xyz="0.206917503877324 0.101500000000002 0.0540300000000024"/>
    <parent link="base_link"/>
    <child link="fl_abd_link"/>
    <axis xyz="1 0 0"/>
    <limit effort="100" lower="-1.5708" upper="1.5708" velocity="100"/>
  </joint>
  <link name="fl_thigh_link">
    <inertial>
      <origin rpy="0 0 0" xyz="0.0014376 0.077483 -0.055275"/>
      <mass value="2.4957"/>
      <inertia ixx="0.0049396" ixy="4.7834E-05" ixz="-3.2241E-06" iyy="0.0054131" iyz="-1.5857E-06" izz="0.0011512"/>
    </inertial>
    <visual>
      <origin rpy="0 0 0" xyz="0 0 0"/>
      <geometry>
        <mesh filename="package://stoch3_description/meshes/fl_thigh_link.STL"/>
      </geometry>
      <material name="">
        <color rgba="0.75294 0.75294 0.75294 1"/>
      </material>
    </visual>
    <collision>
      <origin rpy="0 0 0" xyz="0 0 0"/>
      <geometry>
        <mesh filename="package://stoch3_description/meshes/fl_thigh_link.STL"/>
      </geometry>
    </collision>
  </link>
  <joint name="fl_hip_joint" type="revolute">
    <origin rpy="0 -3.14584042145611E-05 0" xyz="0.06378709521538 0.0139999999999987 0"/>
    <parent link="fl_abd_link"/>
    <child link="fl_thigh_link"/>
    <axis xyz="0 1 0"/>
    <limit effort="100" lower="-1.57078" upper="3.14159" velocity="100"/>
  </joint>
  <link name="fl_shank_link">
    <inertial>
      <origin rpy="0 0 0" xyz="-0.014616 -6.6962E-07 -0.11828"/>
      <mass value="0.37918"/>
      <inertia ixx="0.0021646" ixy="5.617E-09" ixz="-4.4468E-05" iyy="0.0022225" iyz="3.9894E-08" izz="6.6686E-05"/>
    </inertial>
    <visual>
      <origin rpy="0 0 0" xyz="0 0 0"/>
      <geometry>
        <mesh filename="package://stoch3_description/meshes/fl_shank_link.STL"/>
      </geometry>
      <material name="">
        <color rgba="0.79216 0.81961 0.93333 1"/>
      </material>
    </visual>
    <collision>
      <origin rpy="0 0 0" xyz="0 0 0"/>
      <geometry>
        <mesh filename="package://stoch3_description/meshes/fl_shank_link.STL"/>
      </geometry>
    </collision>
  </link>
  <joint name="fl_knee_joint" type="revolute">
    <origin rpy="0 3.14584042149928E-05 0" xyz="0 0.111399999999998 -0.296999999853041"/>
    <parent link="fl_thigh_link"/>
    <child link="fl_shank_link"/>
    <axis xyz="0 1 0"/>
    <limit effort="100" lower="-3.14159" upper="0" velocity="100"/>
  </joint>
  <link name="fr_abd_link">
    <inertial>
      <origin rpy="0 0 0" xyz="0.06156 0.019504 -0.00021624"/>
      <mass value="0.94517"/>
      <inertia ixx="0.00061326" ixy="3.2241E-07" ixz="1.5152E-08" iyy="0.0010243" iyz="-3.8552E-06" izz="0.00060803"/>
    </inertial>
    <visual>
      <origin rpy="0 0 0" xyz="0 0 0"/>
      <geometry>
        <mesh filename="package://stoch3_description/meshes/fr_abd_link.STL"/>
      </geometry>
      <material name="">
        <color rgba="0.79216 0.81961 0.93333 1"/>
      </material>
    </visual>
    <collision>
      <origin rpy="0 0 0" xyz="0 0 0"/>
      <geometry>
        <mesh filename="package://stoch3_description/meshes/fr_abd_link.STL"/>
      </geometry>
    </collision>
  </link>
  <joint name="fr_abd_joint" type="revolute">
    <origin rpy="0 0 0" xyz="0.206925357517166 -0.101499999999999 0.0540300000000003"/>
    <parent link="base_link"/>
    <child link="fr_abd_link"/>
    <axis xyz="1 0 0"/>
    <limit effort="100" lower="-1.5708" upper="1.5708" velocity="100"/>
  </joint>
  <link name="fr_thigh_link">
    <inertial>
      <origin rpy="0 0 0" xyz="0.00144107858196152 -0.07748346487516 -0.0551703662273829"/>
      <mass value="2.49567510872212"/>
      <inertia ixx="0.00493964200419569" ixy="-4.78342957937469E-05" ixz="3.2241369041665E-06" iyy="0.00541305231980369" iyz="-1.61934782864799E-06" izz="0.00115115548345638"/>
    </inertial>
    <visual>
      <origin rpy="0 0 0" xyz="0 0 0"/>
      <geometry>
        <mesh filename="package://stoch3_description/meshes/fr_thigh_link.STL"/>
      </geometry>
      <material name="">
        <color rgba="0.752941176470588 0.752941176470588 0.752941176470588 1"/>
      </material>
    </visual>
    <collision>
      <origin rpy="0 0 0" xyz="0 0 0"/>
      <geometry>
        <mesh filename="package://stoch3_description/meshes/fr_thigh_link.STL"/>
      </geometry>
    </collision>
  </link>
  <joint name="fr_hip_joint" type="revolute">
    <origin rpy="0 3.145840420901E-05 0" xyz="0.06377924157554 -0.0139999999999988 0"/>
    <parent link="fr_abd_link"/>
    <child link="fr_thigh_link"/>
    <axis xyz="0 1 0"/>
    <limit effort="100" lower="-1.57078" upper="3.14159" velocity="100"/>
  </joint>
  <link name="fr_shank_link">
    <inertial>
      <origin rpy="0 0 0" xyz="-0.014616 -6.6962E-07 -0.11828"/>
      <mass value="0.37918"/>
      <inertia ixx="0.0021646" ixy="5.617E-09" ixz="-4.4468E-05" iyy="0.0022225" iyz="3.9894E-08" izz="6.6686E-05"/>
    </inertial>
    <visual>
      <origin rpy="0 0 0" xyz="0 0 0"/>
      <geometry>
        <mesh filename="package://stoch3_description/meshes/fr_shank_link.STL"/>
      </geometry>
      <material name="">
        <color rgba="0.79216 0.81961 0.93333 1"/>
      </material>
    </visual>
    <collision>
      <origin rpy="0 0 0" xyz="0 0 0"/>
      <geometry>
        <mesh filename="package://stoch3_description/meshes/fr_shank_link.STL"/>
      </geometry>
    </collision>
  </link>
  <joint name="fr_knee_joint" type="revolute">
    <origin rpy="0 -3.14584042085783E-05 0" xyz="0 -0.111599999999999 -0.29699999985303"/>
    <parent link="fr_thigh_link"/>
    <child link="fr_shank_link"/>
    <axis xyz="0 1 0"/>
    <limit effort="100" lower="-3.14159" upper="0" velocity="100"/>
  </joint>
  <link name="bl_abd_link">
    <inertial>
      <origin rpy="0 0 0" xyz="0.030793 -0.019504 -0.00042262"/>
      <mass value="0.94517"/>
      <inertia ixx="0.00061091" ixy="-9.6216E-07" ixz="-1.2691E-06" iyy="0.0010243" iyz="1.7068E-06" izz="0.00061038"/>
    </inertial>
    <visual>
      <origin rpy="0 0 0" xyz="0 0 0"/>
      <geometry>
        <mesh filename="package://stoch3_description/meshes/bl_abd_link.STL"/>
      </geometry>
      <material name="">
        <color rgba="0.79216 0.81961 0.93333 1"/>
      </material>
    </visual>
    <collision>
      <origin rpy="0 0 0" xyz="0 0 0"/>
      <geometry>
        <mesh filename="package://stoch3_description/meshes/bl_abd_link.STL"/>
      </geometry>
    </collision>
  </link>
  <joint name="bl_abd_joint" type="revolute">
    <origin rpy="0 0 0" xyz="-0.299402452130055 0.101499999999997 0.0540300000000009"/>
    <parent link="base_link"/>
    <child link="bl_abd_link"/>
    <axis xyz="1 0 0"/>
    <limit effort="100" lower="-1.5708" upper="1.5708" velocity="100"/>
  </joint>
  <link name="bl_thigh_link">
    <inertial>
      <origin rpy="0 0 0" xyz="-0.00144107858108192 0.0774834648849106 -0.0551703662338023"/>
      <mass value="2.49567510818258"/>
      <inertia ixx="0.00493964200383586" ixy="-4.78342957989956E-05" ixz="-3.22413680518202E-06" iyy="0.0054130523194199" iyz="1.61934780851157E-06" izz="0.00115115548343042"/>
    </inertial>
    <visual>
      <origin rpy="0 0 0" xyz="0 0 0"/>
      <geometry>
        <mesh filename="package://stoch3_description/meshes/bl_thigh_link.STL"/>
      </geometry>
      <material name="">
        <color rgba="0.752941176470588 0.752941176470588 0.752941176470588 1"/>
      </material>
    </visual>
    <collision>
      <origin rpy="0 0 0" xyz="0 0 0"/>
      <geometry>
        <mesh filename="package://stoch3_description/meshes/bl_thigh_link.STL"/>
      </geometry>
    </collision>
  </link>
  <joint name="bl_hip_joint" type="revolute">
    <origin rpy="0 -3.14584042145611E-05 0" xyz="0.0286978530373435 0.0139999999999997 0"/>
    <parent link="bl_abd_link"/>
    <child link="bl_thigh_link"/>
    <axis xyz="0 1 0"/>
    <limit effort="100" lower="-1.57078" upper="3.14159" velocity="100"/>
  </joint>
  <link name="bl_shank_link">
    <inertial>
      <origin rpy="0 0 0" xyz="-0.014616 -6.6962E-07 -0.11828"/>
      <mass value="0.37918"/>
      <inertia ixx="0.0021646" ixy="5.617E-09" ixz="-4.4468E-05" iyy="0.0022225" iyz="3.9894E-08" izz="6.6686E-05"/>
    </inertial>
    <visual>
      <origin rpy="0 0 0" xyz="0 0 0"/>
      <geometry>
        <mesh filename="package://stoch3_description/meshes/bl_shank_link.STL"/>
      </geometry>
      <material name="">
        <color rgba="0.79216 0.81961 0.93333 1"/>
      </material>
    </visual>
    <collision>
      <origin rpy="0 0 0" xyz="0 0 0"/>
      <geometry>
        <mesh filename="package://stoch3_description/meshes/bl_shank_link.STL"/>
      </geometry>
    </collision>
  </link>
  <joint name="bl_knee_joint" type="revolute">
    <origin rpy="0 3.14584042094417E-05 0" xyz="0 0.111599999999496 -0.29699999985304"/>
    <parent link="bl_thigh_link"/>
    <child link="bl_shank_link"/>
    <axis xyz="0 1 0"/>
    <limit effort="100" lower="-3.14159" upper="0" velocity="100"/>
  </joint>
  <link name="br_abd_link">
    <inertial>
      <origin rpy="0 0 0" xyz="0.031108 0.019504 -1.7708E-05"/>
      <mass value="0.94517"/>
      <inertia ixx="0.00061475" ixy="8.7419E-07" ixz="3.1106E-06" iyy="0.0010243" iyz="1.7938E-06" izz="0.00060654"/>
    </inertial>
    <visual>
      <origin rpy="0 0 0" xyz="0 0 0"/>
      <geometry>
        <mesh filename="package://stoch3_description/meshes/br_abd_link.STL"/>
      </geometry>
      <material name="">
        <color rgba="0.79216 0.81961 0.93333 1"/>
      </material>
    </visual>
    <collision>
      <origin rpy="0 0 0" xyz="0 0 0"/>
      <geometry>
        <mesh filename="package://stoch3_description/meshes/br_abd_link.STL"/>
      </geometry>
    </collision>
  </link>
  <joint name="br_abd_joint" type="revolute">
    <origin rpy="0 0 0" xyz="-0.299402452130055 -0.101500000000005 0.0540300000000005"/>
    <parent link="base_link"/>
    <child link="br_abd_link"/>
    <axis xyz="1 0 0"/>
    <limit effort="100" lower="-1.5708" upper="1.5708" velocity="100"/>
  </joint>
  <link name="br_thigh_link">
    <inertial>
      <origin rpy="0 0 0" xyz="-0.00150303818321485 -0.0774834645949825 -0.0552213173300917"/>
      <mass value="2.49567512655825"/>
      <inertia ixx="0.0049362160738861" ixy="4.96261951245898E-05" ixz="2.5269174510805E-06" iyy="0.00541305233737715" iyz="1.18125628096648E-07" izz="0.00115458143484649"/>
    </inertial>
    <visual>
      <origin rpy="0 0 0" xyz="0 0 0"/>
      <geometry>
        <mesh filename="package://stoch3_description/meshes/br_thigh_link.STL"/>
      </geometry>
      <material name="">
        <color rgba="0.752941176470588 0.752941176470588 0.752941176470588 1"/>
      </material>
    </visual>
    <collision>
      <origin rpy="0 0 0" xyz="0 0 0"/>
      <geometry>
        <mesh filename="package://stoch3_description/meshes/br_thigh_link.STL"/>
      </geometry>
    </collision>
  </link>
  <joint name="br_hip_joint" type="revolute">
    <origin rpy="0 3.14584042201122E-05 0" xyz="0.0286978530373517 -0.0139999999999956 0"/>
    <parent link="br_abd_link"/>
    <child link="br_thigh_link"/>
    <axis xyz="0 1 0"/>
    <limit effort="100" lower="-1.57078" upper="3.14159" velocity="100"/>
  </joint>
  <link name="br_shank_link">
    <inertial>
      <origin rpy="0 0 0" xyz="-0.014616 -6.6962E-07 -0.11828"/>
      <mass value="0.37918"/>
      <inertia ixx="0.0021646" ixy="5.617E-09" ixz="-4.4468E-05" iyy="0.0022225" iyz="3.9894E-08" izz="6.6686E-05"/>
    </inertial>
    <visual>
      <origin rpy="0 0 0" xyz="0 0 0"/>
      <geometry>
        <mesh filename="package://stoch3_description/meshes/br_shank_link.STL"/>
      </geometry>
      <material name="">
        <color rgba="0.79216 0.81961 0.93333 1"/>
      </material>
    </visual>
    <collision>
      <origin rpy="0 0 0" xyz="0 0 0"/>
      <geometry>
        <mesh filename="package://stoch3_description/meshes/br_shank_link.STL"/>
      </geometry>
    </collision>
  </link>
  <joint name="br_knee_joint" type="revolute">
    <origin rpy="0 -3.14584042141294E-05 0" xyz="0 -0.111600000000005 -0.296999999853014"/>
    <parent link="br_thigh_link"/>
    <child link="br_shank_link"/>
    <axis xyz="0 1 0"/>
    <limit effort="100" lower="-3.14159" upper="0" velocity="100"/>
  </joint>
  <link name="fl_foot_link"/>
  <joint name="fl_ankle_joint" type="fixed">
    <parent link="fl_shank_link"/>
    <child link="fl_foot_link"/>
    <origin rpy="0 0 0" xyz="0 0 -0.3"/>
  </joint>
  <link name="fr_foot_link"/>
  <joint name="fr_ankle_joint" type="fixed">
    <parent link="fr_shank_link"/>
    <child link="fr_foot_link"/>
    <origin rpy="0 0 0" xyz="0 0 -0.3"/>
  </joint>
  <link name="bl_foot_link"/>
  <joint name="bl_ankle_joint" type="fixed">
    <parent link="bl_shank_link"/>
    <child link="bl_foot_link"/>
    <origin rpy="0 0 0" xyz="0 0 -0.3"/>
  </joint>
  <link name="br_foot_link"/>
  <joint name="br_ankle_joint" type="fixed">
    <parent link="br_shank_link"/>
    <child link="br_foot_link"/>
    <origin rpy="0 0 0" xyz="0 0 -0.3"/>
  </joint>
  <transmission name="fl_abd_trans">
    <type>transmission_interface/SimpleTransmission</type>
    <joint name="fl_abd_joint">
      <hardwareInterface>hardware_interface/PosVelEffJointInterface</hardwareInterface>
    </joint>
    <actuator name="fl_abd_motor">
      <mechanicalReduction>1</mechanicalReduction>
    </actuator>
  </transmission>
  <transmission name="fl_hip_trans">
    <type>transmission_interface/SimpleTransmission</type>
    <joint name="fl_hip_joint">
      <hardwareInterface>hardware_interface/PosVelEffJointInterface</hardwareInterface>
    </joint>
    <actuator name="fl_hip_motor">
      <mechanicalReduction>1</mechanicalReduction>
    </actuator>
  </transmission>
  <transmission name="fl_knee_trans">
    <type>transmission_interface/SimpleTransmission</type>
    <joint name="fl_knee_joint">
      <hardwareInterface>hardware_interface/PosVelEffJointInterface</hardwareInterface>
    </joint>
    <actuator name="fl_knee_motor">
      <mechanicalReduction>1</mechanicalReduction>
    </actuator>
  </transmission>
  <transmission name="bl_abd_trans">
    <type>transmission_interface/SimpleTransmission</type>
    <joint name="bl_abd_joint">
      <hardwareInterface>hardware_interface/PosVelEffJointInterface</hardwareInterface>
    </joint>
    <actuator name="bl_abd_motor">
      <mechanicalReduction>1</mechanicalReduction>
    </actuator>
  </transmission>
  <transmission name="bl_hip_trans">
    <type>transmission_interface/SimpleTransmission</type>
    <joint name="bl_hip_joint">
      <hardwareInterface>hardware_interface/PosVelEffJointInterface</hardwareInterface>
    </joint>
    <actuator name="bl_hip_motor">
      <mechanicalReduction>1</mechanicalReduction>
    </actuator>
  </transmission>
  <transmission name="bl_knee_trans">
    <type>transmission_interface/SimpleTransmission</type>
    <joint name="bl_knee_joint">
      <hardwareInterface>hardware_interface/PosVelEffJointInterface</hardwareInterface>
    </joint>
    <actuator name="bl_knee_motor">
      <mechanicalReduction>1</mechanicalReduction>
    </actuator>
  </transmission>
  <transmission name="fr_abd_trans">
    <type>transmission_interface/SimpleTransmission</type>
    <joint name="fr_abd_joint">
      <hardwareInterface>hardware_interface/PosVelEffJointInterface</hardwareInterface>
    </joint>
    <actuator name="fr_abd_motor">
      <mechanicalReduction>1</mechanicalReduction>
    </actuator>
  </transmission>
  <transmission name="fr_hip_trans">
    <type>transmission_interface/SimpleTransmission</type>
    <joint name="fr_hip_joint">
      <hardwareInterface>hardware_interface/PosVelEffJointInterface</hardwareInterface>
    </joint>
    <actuator name="fr_hip_motor">
      <mechanicalReduction>1</mechanicalReduction>
    </actuator>
  </transmission>
  <transmission name="fr_knee_trans">
    <type>transmission_interface/SimpleTransmission</type>
    <joint name="fr_knee_joint">
      <hardwareInterface>hardware_interface/PosVelEffJointInterface</hardwareInterface>
    </joint>
    <actuator name="fr_knee_motor">
      <mechanicalReduction>1</mechanicalReduction>
    </actuator>
  </transmission>
  <transmission name="br_abd_trans">
    <type>transmission_interface/SimpleTransmission</type>
    <joint name="br_abd_joint">
      <hardwareInterface>hardware_interface/PosVelEffJointInterface</hardwareInterface>
    </joint>
    <actuator name="br_abd_motor">
      <mechanicalReduction>1</mechanicalReduction>
    </actuator>
  </transmission>
  <transmission name="br_hip_trans">
    <type>transmission_interface/SimpleTransmission</type>
    <joint name="br_hip_joint">
      <hardwareInterface>hardware_interface/PosVelEffJointInterface</hardwareInterface>
    </joint>
    <actuator name="br_hip_motor">
      <mechanicalReduction>1</mechanicalReduction>
    </actuator>
  </transmission>
  <transmission name="br_knee_trans">
    <type>transmission_interface/SimpleTransmission</type>
    <joint name="br_knee_joint">
      <hardwareInterface>hardware_interface/PosVelEffJointInterface</hardwareInterface>
    </joint>
    <actuator name="br_knee_motor">
      <mechanicalReduction>1</mechanicalReduction>
    </actuator>
  </transmission>
  <gazebo reference="base_link_link">
    <material>Gazebo/White</material>
    <kp>10000000.0</kp>
    <kd>1.0</kd>
    <mu1>4.0</mu1>
    <mu2>4.0</mu2>
    <maxVel>0.0</maxVel>
    <minDepth>0.001</minDepth>
  </gazebo>
  <gazebo reference="fl_abd_link">
    <material>Gazebo/Grey</material>
    <kp>10000000.0</kp>
    <kd>1.0</kd>
    <mu1>4.0</mu1>
    <mu2>4.0</mu2>
    <maxVel>0.0</maxVel>
    <minDepth>0.001</minDepth>
  </gazebo>
  <gazebo reference="bl_abd_link">
    <material>Gazebo/Grey</material>
    <kp>10000000.0</kp>
    <kd>1.0</kd>
    <mu1>4.0</mu1>
    <mu2>4.0</mu2>
    <maxVel>0.0</maxVel>
    <minDepth>0.001</minDepth>
  </gazebo>
  <gazebo reference="fr_abd_link">
    <material>Gazebo/Grey</material>
    <kp>10000000.0</kp>
    <kd>1.0</kd>
    <mu1>4.0</mu1>
    <mu2>4.0</mu2>
    <maxVel>0.0</maxVel>
    <minDepth>0.001</minDepth>
  </gazebo>
  <gazebo reference="br_abd_link">
    <material>Gazebo/Grey</material>
    <kp>10000000.0</kp>
    <kd>1.0</kd>
    <mu1>4.0</mu1>
    <mu2>4.0</mu2>
    <maxVel>0.0</maxVel>
    <minDepth>0.001</minDepth>
  </gazebo>
  <gazebo reference="fl_thigh_link">
    <material>Gazebo/DarkGrey</material>
    <kp>10000000.0</kp>
    <kd>1.0</kd>
    <mu1>4.0</mu1>
    <mu2>4.0</mu2>
    <maxVel>0.0</maxVel>
    <minDepth>0.001</minDepth>
  </gazebo>
  <gazebo reference="bl_thigh_link">
    <material>Gazebo/DarkGrey</material>
    <kp>10000000.0</kp>
    <kd>1.0</kd>
    <mu1>4.0</mu1>
    <mu2>4.0</mu2>
    <maxVel>0.0</maxVel>
    <minDepth>0.001</minDepth>
  </gazebo>
  <gazebo reference="fr_thigh_link">
    <material>Gazebo/DarkGrey</material>
    <kp>10000000.0</kp>
    <kd>1.0</kd>
    <mu1>4.0</mu1>
    <mu2>4.0</mu2>
    <maxVel>0.0</maxVel>
    <minDepth>0.001</minDepth>
  </gazebo>
  <gazebo reference="br_thigh_link">
    <material>Gazebo/DarkGrey</material>
    <kp>10000000.0</kp>
    <kd>1.0</kd>
    <mu1>4.0</mu1>
    <mu2>4.0</mu2>
    <maxVel>0.0</maxVel>
    <minDepth>0.001</minDepth>
  </gazebo>
  <gazebo reference="fl_shank_link">
    <material>Gazebo/Grey</material>
    <kp>10000000.0</kp>
    <kd>1.0</kd>
    <mu1>4.0</mu1>
    <mu2>4.0</mu2>
    <maxVel>0.0</maxVel>
    <minDepth>0.001</minDepth>
  </gazebo>
  <gazebo reference="bl_shank_link">
    <material>Gazebo/Grey</material>
    <kp>10000000.0</kp>
    <kd>1.0</kd>
    <mu1>4.0</mu1>
    <mu2>4.0</mu2>
    <maxVel>0.0</maxVel>
    <minDepth>0.001</minDepth>
  </gazebo>
  <gazebo reference="fr_shank_link">
    <material>Gazebo/Grey</material>
    <kp>10000000.0</kp>
    <kd>1.0</kd>
    <mu1>4.0</mu1>
    <mu2>4.0</mu2>
    <maxVel>0.0</maxVel>
    <minDepth>0.001</minDepth>
  </gazebo>
  <gazebo reference="br_shank_link">
    <material>Gazebo/Grey</material>
    <kp>10000000.0</kp>
    <kd>1.0</kd>
    <mu1>4.0</mu1>
    <mu2>4.0</mu2>
    <maxVel>0.0</maxVel>
    <minDepth>0.001</minDepth>
  </gazebo>
  <!-- Enable the Joint Control -->
  <gazebo>
    <plugin filename="libgazebo_ros_control.so" name="gazebo_ros_control">
      <legacyModeNS>true</legacyModeNS>
      <robotNamespace>stoch3</robotNamespace>
      <robotSimType>stoch3_gazebo/Stoch3RobotHWSim</robotSimType>
    </plugin>
  </gazebo>
  <gazebo>
    <self_collide>1</self_collide>
  </gazebo>
  <!--
        <gazebo>
            <plugin filename="libgazebo_ros_p3d.so" name="p3d_base_controller">
                <alwaysOn>true</alwaysOn>
                <updateRate>10.0</updateRate>
                <bodyName>base_link</bodyName>
                <topicName>odom/ground_truth</topicName>
                <gaussianNoise>0.01</gaussianNoise>
                <frameName>world</frameName>
                <xyzOffsets>0 0 0</xyzOffsets>
                <rpyOffsets>0 0 0</rpyOffsets>
            </plugin>
        </gazebo>
        -->
  <link name="imu_link_1">
    <inertial>
      <mass value="0.001"/>
      <origin rpy="0 0 0" xyz="0 0 0"/>
      <inertia ixx="1e-09" ixy="0.0" ixz="0.0" iyy="1e-09" iyz="0.0" izz="1e-09"/>
    </inertial>
    <visual>
      <origin rpy="0 0 0" xyz="0 0 0"/>
      <geometry>
        <box size="0.005 0.005 0.005"/>
      </geometry>
      <material name="">
        <color rgba="0.6 0.8 0.1 1"/>
      </material>
    </visual>
  </link>
  <joint name="imu_joint_1" type="fixed">
    <parent link="base_link"/>
    <child link="imu_link_1"/>
    <origin rpy="0.0 0.0 0.0" xyz="0.0 0.0 0.005"/>
  </joint>
  <gazebo>
    <plugin filename="libhector_gazebo_ros_imu.so" name="imu_1_controller">
      <updateRate>100</updateRate>
      <bodyName>imu_link_1</bodyName>
      <topicName>sensors/imu_1</topicName>
      <accelDrift>0.005 0.005 0.005</accelDrift>
      <accelGaussianNoise>0.005 0.005 0.005</accelGaussianNoise>
      <rateDrift>0.005 0.005 0.005 </rateDrift>
      <rateGaussianNoise>0.005 0.005 0.005</rateGaussianNoise>
      <headingDrift>0.005</headingDrift>
      <headingGaussianNoise>0.005</headingGaussianNoise>
    </plugin>
    <material>Gazebo/Yellow</material>
  </gazebo>
</robot>
